import React from 'react';
import { render, screen } from '@testing-library/react';
import userEvent from '@testing-library/user-event';
import { ErrorBoundary } from '../error-boundary';

// Component that throws an error
const ThrowError = ({ shouldThrow }: { shouldThrow: boolean }) => {
  if (shouldThrow) {
    throw new Error('Test error');
  }
  return <div>No error</div>;
};

describe('ErrorBoundary', () => {
  // Suppress console.error for these tests
  const originalError = console.error;
  beforeAll(() => {
    console.error = jest.fn();
  });

  afterAll(() => {
    console.error = originalError;
  });

  it('should render children when there is no error', () => {
    render(
      <ErrorBoundary>
        <ThrowError shouldThrow={false} />
      </ErrorBoundary>
    );

    expect(screen.getByText('No error')).toBeInTheDocument();
  });

  it('should render error UI when there is an error', () => {
    render(
      <ErrorBoundary>
        <ThrowError shouldThrow={true} />
      </ErrorBoundary>
    );

    expect(screen.getByText('Something went wrong')).toBeInTheDocument();
    expect(screen.getByText('Test error')).toBeInTheDocument();
    expect(screen.getByRole('button', { name: /try again/i })).toBeInTheDocument();
  });

  it('should render custom fallback when provided', () => {
    const customFallback = <div>Custom error message</div>;

    render(
      <ErrorBoundary fallback={customFallback}>
        <ThrowError shouldThrow={true} />
      </ErrorBoundary>
    );

    expect(screen.getByText('Custom error message')).toBeInTheDocument();
    expect(screen.queryByText('Something went wrong')).not.toBeInTheDocument();
  });

  it('should reset error state when retry button is clicked', async () => {
    const user = userEvent.setup();
    
    const TestComponent = () => {
      const [shouldThrow, setShouldThrow] = React.useState(true);
      
      React.useEffect(() => {
        // After 100ms, stop throwing error
        const timer = setTimeout(() => setShouldThrow(false), 100);
        return () => clearTimeout(timer);
      }, []);

      return <ThrowError shouldThrow={shouldThrow} />;
    };

    render(
      <ErrorBoundary>
        <TestComponent />
      </ErrorBoundary>
    );

    // Initially should show error
    expect(screen.getByText('Something went wrong')).toBeInTheDocument();

    // Wait for the component to stop throwing
    await new Promise(resolve => setTimeout(resolve, 150));

    // Click retry button
    const retryButton = screen.getByRole('button', { name: /try again/i });
    await user.click(retryButton);

    // Should now show the component without error
    expect(screen.getByText('No error')).toBeInTheDocument();
    expect(screen.queryByText('Something went wrong')).not.toBeInTheDocument();
  });

  it('should handle errors without messages', () => {
    const ThrowErrorWithoutMessage = () => {
      throw new Error();
    };

    render(
      <ErrorBoundary>
        <ThrowErrorWithoutMessage />
      </ErrorBoundary>
    );

    expect(screen.getByText('Something went wrong')).toBeInTheDocument();
    expect(screen.getByText('An unexpected error occurred')).toBeInTheDocument();
  });
});